[2024-12-01 14:54:00,577][zerorpc.core][ERROR] - 
Traceback (most recent call last):
  File "/home/my/anaconda3/envs/m3p2i-aip/lib/python3.8/site-packages/zerorpc/core.py", line 153, in _async_task
    functor.pattern.process_call(self._context, bufchan, event, functor)
  File "/home/my/anaconda3/envs/m3p2i-aip/lib/python3.8/site-packages/zerorpc/patterns.py", line 30, in process_call
    result = functor(*req_event.args)
  File "/home/my/anaconda3/envs/m3p2i-aip/lib/python3.8/site-packages/zerorpc/decorators.py", line 44, in __call__
    return self._functor(*args, **kargs)
  File "reactive_tamp.py", line 51, in run_tamp
    self.sim._dof_state[:] = bytes_to_torch(dof_state)
RuntimeError: The expanded size of the tensor (18) must match the existing size (4) at non-singleton dimension 1.  Target sizes: [200, 18].  Tensor sizes: [4]
